Workbook

Sheet Welcome
B2: ✦ Bold & Balanced Wedding Bible ✦
B4: Modern Luxury Wedding Planning System
B6: ✦ OUR WEDDING DETAILS ✦
B7: Bride's Name
B8: Groom's Name
B9: Wedding Date
B10: Ceremony Venue
B11: Reception Venue
B12: Wedding City & State
B14: ✦ DAYS UNTIL YOUR BIG DAY ✦
B15: =IFERROR(C9-TODAY(),"✦ Enter your wedding date above ✦")
B17: days to go — You've got this, bride! 💍
B19: ✦ QUICK STATS ✦
B20: 💰 Total Budget | D20: 👥 Guests Invited | F20: ✅ Tasks Done
B21: =IFERROR('Budget Detail'!B3,0) | D21: =IFERROR(COUNTA('Guest List'!B:B)-1,0) | F21: =IFERROR(COUNTIF(Checklist!D:D,"✓ Done"),0)
B23: ✦ NAVIGATE YOUR PLANNER ✦
B24: 📋 Wedding Overview | D24: 💰 Budget Dashboard
B25: 👥 Guest List | D25: 🤝 Vendor Tracker
B26: 🕐 Day-of Timeline | D26: ✅ Master Checklist
B27: 💐 Bridal Party | D27: 🪑 Seating Chart
B28: 🎁 Gift Registry | D28: ✈️ Honeymoon Planner

Sheet Overview
B1: ✦ WEDDING OVERVIEW ✦
B3: Your complete wedding details — fill in each section
B5: 💍 THE COUPLE | D5: 🎨 WEDDING STYLE
B6: Bride's Full Name | D6: Wedding Theme
B7: Groom's Full Name | D7: Wedding Colors
B8: Wedding Date | D8: Wedding Season
B9: Engagement Date | D9: Dress Code
B10: Anniversary | D10: Wedding Hashtag
B12: 📍 CEREMONY | D12: 📅 IMPORTANT DATES
B13: Ceremony Venue | D13: Save the Date Sent
B14: Address | D14: Invitations Sent
B15: City / State | D15: RSVP Deadline
B16: Ceremony Time | D16: Final Headcount Due
B17: Ceremony End Time | D17: Rehearsal Date
B19: 🍽️ RECEPTION | D19: 💰 BUDGET SNAPSHOT
B20: Reception Venue | D20: Total Budget | E20: ='Budget Detail'!B3
B21: Address | D21: Total Estimated | E21: ='Budget Detail'!B4
B22: City / State | D22: Total Spent | E22: ='Budget Detail'!B5
B23: Reception Start | D23: Total Paid | E23: ='Budget Detail'!B5
B24: Reception End | D24: Balance Remaining | E24: ='Budget Detail'!B6
B26: 📞 KEY CONTACTS | D26: 👰 WEDDING PARTY
B27: Wedding Planner | D27: Maid of Honor
B28: Planner Phone | D28: Best Man
B29: Officiant | D29: Flower Girl(s)
B30: Officiant Phone | D30: Ring Bearer
B31: Emergency Contact | D31: Total Bridesmaids
B32: Emergency Phone | D32: Total Groomsmen

Sheet Budget Dashboard
B1: ✦ BUDGET DASHBOARD ✦
B3: Auto-updating totals and category breakdown — no manual entry needed
B5: ✦ BUDGET SUMMARY ✦
B6: 💰 Total Budget | C6: 📊 Estimated Total | D6: 💳 Actual Spent | E6: ✅ Total Paid | F6: ⚠️ Balance Due
B7: =B8 | C7: =C8 | D7: =D8 | E7: =E8 | F7: =F8
B8: =C27 | C8: =D27 | D8: =E27 | E8: =F27 | F8: =G27
B9: ✦ BUDGET BY CATEGORY ✦
B10: Category | C10: Budget | D10: Estimated | E10: Actual Spent | F10: Paid | G10: Balance Due
B11: Venue | C11: =IFERROR(SUMIF('Budget Detail'!A:A,B11,'Budget Detail'!C:C),0) | D11: =IFERROR(SUMIF('Budget Detail'!A:A,B11,'Budget Detail'!D:D),0) | E11: =IFERROR(SUMIF('Budget Detail'!A:A,B11,'Budget Detail'!E:E),0) | F11: =IFERROR(SUMIF('Budget Detail'!A:A,B11,'Budget Detail'!F:F),0) | G11: =IFERROR(D11-E11,0)
B12: Catering | C12: =IFERROR(SUMIF('Budget Detail'!A:A,B12,'Budget Detail'!C:C),0) | D12: =IFERROR(SUMIF('Budget Detail'!A:A,B12,'Budget Detail'!D:D),0) | E12: =IFERROR(SUMIF('Budget Detail'!A:A,B12,'Budget Detail'!E:E),0) | F12: =IFERROR(SUMIF('Budget Detail'!A:A,B12,'Budget Detail'!F:F),0) | G12: =IFERROR(D12-E12,0)
B13: Photography | C13: =IFERROR(SUMIF('Budget Detail'!A:A,B13,'Budget Detail'!C:C),0) | D13: =IFERROR(SUMIF('Budget Detail'!A:A,B13,'Budget Detail'!D:D),0) | E13: =IFERROR(SUMIF('Budget Detail'!A:A,B13,'Budget Detail'!E:E),0) | F13: =IFERROR(SUMIF('Budget Detail'!A:A,B13,'Budget Detail'!F:F),0) | G13: =IFERROR(D13-E13,0)
B14: Videography | C14: =IFERROR(SUMIF('Budget Detail'!A:A,B14,'Budget Detail'!C:C),0) | D14: =IFERROR(SUMIF('Budget Detail'!A:A,B14,'Budget Detail'!D:D),0) | E14: =IFERROR(SUMIF('Budget Detail'!A:A,B14,'Budget Detail'!E:E),0) | F14: =IFERROR(SUMIF('Budget Detail'!A:A,B14,'Budget Detail'!F:F),0) | G14: =IFERROR(D14-E14,0)
B15: Florals | C15: =IFERROR(SUMIF('Budget Detail'!A:A,B15,'Budget Detail'!C:C),0) | D15: =IFERROR(SUMIF('Budget Detail'!A:A,B15,'Budget Detail'!D:D),0) | E15: =IFERROR(SUMIF('Budget Detail'!A:A,B15,'Budget Detail'!E:E),0) | F15: =IFERROR(SUMIF('Budget Detail'!A:A,B15,'Budget Detail'!F:F),0) | G15: =IFERROR(D15-E15,0)
B16: Music / DJ | C16: =IFERROR(SUMIF('Budget Detail'!A:A,B16,'Budget Detail'!C:C),0) | D16: =IFERROR(SUMIF('Budget Detail'!A:A,B16,'Budget Detail'!D:D),0) | E16: =IFERROR(SUMIF('Budget Detail'!A:A,B16,'Budget Detail'!E:E),0) | F16: =IFERROR(SUMIF('Budget Detail'!A:A,B16,'Budget Detail'!F:F),0) | G16: =IFERROR(D16-E16,0)
B17: Attire & Beauty | C17: =IFERROR(SUMIF('Budget Detail'!A:A,B17,'Budget Detail'!C:C),0) | D17: =IFERROR(SUMIF('Budget Detail'!A:A,B17,'Budget Detail'!D:D),0) | E17: =IFERROR(SUMIF('Budget Detail'!A:A,B17,'Budget Detail'!E:E),0) | F17: =IFERROR(SUMIF('Budget Detail'!A:A,B17,'Budget Detail'!F:F),0) | G17: =IFERROR(D17-E17,0)
B18: Transportation | C18: =IFERROR(SUMIF('Budget Detail'!A:A,B18,'Budget Detail'!C:C),0) | D18: =IFERROR(SUMIF('Budget Detail'!A:A,B18,'Budget Detail'!D:D),0) | E18: =IFERROR(SUMIF('Budget Detail'!A:A,B18,'Budget Detail'!E:E),0) | F18: =IFERROR(SUMIF('Budget Detail'!A:A,B18,'Budget Detail'!F:F),0) | G18: =IFERROR(D18-E18,0)
B19: Stationery | C19: =IFERROR(SUMIF('Budget Detail'!A:A,B19,'Budget Detail'!C:C),0) | D19: =IFERROR(SUMIF('Budget Detail'!A:A,B19,'Budget Detail'!D:D),0) | E19: =IFERROR(SUMIF('Budget Detail'!A:A,B19,'Budget Detail'!E:E),0) | F19: =IFERROR(SUMIF('Budget Detail'!A:A,B19,'Budget Detail'!F:F),0) | G19: =IFERROR(D19-E19,0)
B20: Rings | C20: =IFERROR(SUMIF('Budget Detail'!A:A,B20,'Budget Detail'!C:C),0) | D20: =IFERROR(SUMIF('Budget Detail'!A:A,B20,'Budget Detail'!D:D),0) | E20: =IFERROR(SUMIF('Budget Detail'!A:A,B20,'Budget Detail'!E:E),0) | F20: =IFERROR(SUMIF('Budget Detail'!A:A,B20,'Budget Detail'!F:F),0) | G20: =IFERROR(D20-E20,0)
B21: Honeymoon | C21: =IFERROR(SUMIF('Budget Detail'!A:A,B21,'Budget Detail'!C:C),0) | D21: =IFERROR(SUMIF('Budget Detail'!A:A,B21,'Budget Detail'!D:D),0) | E21: =IFERROR(SUMIF('Budget Detail'!A:A,B21,'Budget Detail'!E:E),0) | F21: =IFERROR(SUMIF('Budget Detail'!A:A,B21,'Budget Detail'!F:F),0) | G21: =IFERROR(D21-E21,0)
B22: Gifts & Favors | C22: =IFERROR(SUMIF('Budget Detail'!A:A,B22,'Budget Detail'!C:C),0) | D22: =IFERROR(SUMIF('Budget Detail'!A:A,B22,'Budget Detail'!D:D),0) | E22: =IFERROR(SUMIF('Budget Detail'!A:A,B22,'Budget Detail'!E:E),0) | F22: =IFERROR(SUMIF('Budget Detail'!A:A,B22,'Budget Detail'!F:F),0) | G22: =IFERROR(D22-E22,0)
... B26: Other | C26: =IFERROR(SUMIF('Budget Detail'!A:A,B26,'Budget Detail'!C:C),0) | D26: =IFERROR(SUMIF('Budget Detail'!A:A,B26,'Budget Detail'!D:D),0) | E26: =IFERROR(SUMIF('Budget Detail'!A:A,B26,'Budget Detail'!E:E),0) | F26: =IFERROR(SUMIF('Budget Detail'!A:A,B26,'Budget Detail'!F:F),0) | G26: =IFERROR(D26-E26,0)
B27: TOTAL | C27: =SUM(C11:C26) | D27: =SUM(D11:D26) | E27: =SUM(E11:E26) | F27: =SUM(F11:F26) | G27: =SUM(G11:G26)

Sheet Budget Detail
B1: ✦ BUDGET DETAIL ✦
B3: Add every expense below — all totals update automatically
B5: Total Budget | E5: ← Enter your total budget in C5
B6: Total Estimated | C6: =SUM(E9:E2000)
B7: Total Paid | C7: =SUM(F9:F2000)
B8: Balance Remaining | C8: =B6-B7
B9: Category | C9: Item / Description | D9: Budget Allocated | E9: Estimated Cost | F9: Actual / Paid | G9: Balance | H9: Status | I9: Notes
G10: =IFERROR(E10-F10,0)
G11: =IFERROR(E11-F11,0)
G12: =IFERROR(E12-F12,0)
G13: =IFERROR(E13-F13,0)
G14: =IFERROR(E14-F14,0)
G15: =IFERROR(E15-F15,0)
G16: =IFERROR(E16-F16,0)
G17: =IFERROR(E17-F17,0)
G18: =IFERROR(E18-F18,0)
G19: =IFERROR(E19-F19,0)
G20: =IFERROR(E20-F20,0)
G21: =IFERROR(E21-F21,0)
... G59: =IFERROR(E59-F59,0)

Sheet Guest List
B1: ✦ GUEST LIST ✦
B4: Total Invited | D4: RSVP Yes | F4: RSVP No | H4: Pending | J4: Total Adults | L4: Total Children
B5: =IFERROR(COUNTA(C8:C2000),0) | D5: =IFERROR(COUNTIF(H8:H2000,"Yes"),0) | F5: =IFERROR(COUNTIF(H8:H2000,"No"),0) | H5: =IFERROR(COUNTIF(H8:H2000,"Pending"),0) | J5: =IFERROR(SUM(F8:F2000),0) | L5: =IFERROR(SUM(G8:G2000),0)
B7: # | C7: First Name | D7: Last Name | E7: Group | F7: Email | G7: Adults | H7: Children | I7: RSVP | J7: Meal Choice | K7: Table # | L7: +1? | M7: Phone / Notes | N7: Gift Received? | O7: Thank You?
B8: 1
B9: 2
B10: 3
B11: 4
B12: 5
B13: 6
B14: 7
B15: 8
B16: 9
B17: 10
B18: 11
B19: 12
... B107: 100

Sheet Vendors
B1: ✦ VENDOR TRACKER ✦
B3: Track every vendor, contract, deposit, and balance in one place
B5: Category | C5: Vendor / Company | D5: Contact Name | E5: Phone | F5: Email | G5: Website | H5: Contract? | I5: Deposit Paid | J5: Balance Due | K5: Total Cost | L5: Status | M5: Notes

Sheet Timeline
B1: ✦ DAY-OF TIMELINE ✦
B3: Your complete minute-by-minute wedding day schedule
B5: Time | C5: Event / Activity | D5: Location | E5: Responsible Person | F5: Vendor / Contact | G5: Notes

Sheet Checklist
B1: ✦ MASTER WEDDING CHECKLIST ✦
B3: Total Tasks | D3: Completed | F3: In Progress | H3: % Complete
B4: =IFERROR(COUNTA(C7:C2000),0) | D4: =IFERROR(COUNTIF(D7:D2000,"✓ Done"),0) | F4: =IFERROR(COUNTIF(D7:D2000,"In Progress"),0) | H4: =IFERROR(D4/B4,0)
B6: Timeframe | C6: Task | D6: Status | E6: Due Date | F6: Assigned To | G6: Notes

Sheet Bridal Party
B1: ✦ BRIDAL PARTY ✦
B3: Track your wedding party details, attire & measurements
B5: Role | C5: Full Name | D5: Phone | E5: Email | F5: Dress / Suit Colour | G5: Dress Size / Suit Size | H5: Attire Ordered? | I5: Fitting Date | J5: Notes

Sheet Seating
B1: ✦ SEATING CHART PLANNER ✦
B3: Assign guests to tables — update as RSVPs come in
B5: 💡 TIP: Enter guest names in the columns below each table number
B7: 🪑 Head Table — Bridal Party | E7: 🪑 Table 2 — Immediate Family
B8: Seats 8 | E8: Seats 8
B9: 1 | E9: 1
B10: 2 | E10: 2
B11: 3 | E11: 3
B12: 4 | E12: 4
B13: 5 | E13: 5
B14: 6 | E14: 6
B15: 7 | E15: 7
B16: 8 | E16: 8
B21: 🪑 Table 3 — Bride's Friends | E21: 🪑 Table 4 — Groom's Friends
B22: Seats 8 | E22: Seats 8
B23: 1 | E23: 1
B24: 2 | E24: 2
B25: 3 | E25: 3
B26: 4 | E26: 4
B27: 5 | E27: 5
B28: 6 | E28: 6
B29: 7 | E29: 7
B30: 8 | E30: 8
B35: 🪑 Table 5 | E35: 🪑 Table 6
B36: Seats 8 | E36: Seats 8
B37: 1 | E37: 1
B38: 2 | E38: 2
B39: 3 | E39: 3
B40: 4 | E40: 4
B41: 5 | E41: 5
B42: 6 | E42: 6
B43: 7 | E43: 7
B44: 8 | E44: 8
B49: 🪑 Table 7 | E49: 🪑 Table 8
B50: Seats 8 | E50: Seats 8
B51: 1 | E51: 1
B52: 2 | E52: 2
B53: 3 | E53: 3
B54: 4 | E54: 4
B55: 5 | E55: 5
...

Sheet Registry
B1: ✦ GIFT REGISTRY TRACKER ✦
B3: Track registry items, purchases, and thank-you cards
B5: Total Items | D5: Purchased | F5: Total Value | H5: Thank Yous Sent
B6: =IFERROR(COUNTA(C8:C2000),0) | D6: =IFERROR(COUNTIF(G8:G2000,"Yes"),0) | F6: =IFERROR(SUM(D8:D2000),0) | H6: =IFERROR(COUNTIF(J8:J2000,"Yes"),0)
B8: Item / Gift | C8: Store / Registry | D8: Price | E8: Qty Wanted | F8: Qty Received | G8: Purchased? | H8: Received From | I8: Date Received | J8: Thank You? | K8: Notes

Sheet Honeymoon
B1: ✦ HONEYMOON PLANNER ✦
B3: Plan your perfect honeymoon — itinerary, budget & packing
B5: ✦ DESTINATION & DETAILS ✦
B6: Destination
B7: Departure Date
B8: Return Date
B9: Number of Nights
B10: Hotel / Resort
B11: Confirmation #
B12: Total Budget
B14: ✦ DAILY ITINERARY ✦
B15: Day # | C15: Day | D15: Activity / Plan | E15: Location | F15: Booking Ref. | G15: Cost | H15: Date | I15: Notes
B31: ✦ HONEYMOON BUDGET SUMMARY ✦
B32: Flights
B33: Accommodation
B34: Activities & Tours
B35: Food & Dining
B36: Shopping
B37: Travel Insurance
B38: Other
B39: TOTAL SPEND | C39: =SUM(C32:C38)
